[2025-05-01T02:30:01.817+0000] {local_task_job_runner.py:123} INFO - ::group::Pre task execution logs
[2025-05-01T02:30:01.834+0000] {taskinstance.py:2612} INFO - Dependencies all met for dep_context=non-requeueable deps ti=<TaskInstance: tesla_stock_sentiment__etl.load_stock_data_to_snowflake scheduled__2025-04-30T02:30:00+00:00 [queued]>
[2025-05-01T02:30:01.843+0000] {taskinstance.py:2612} INFO - Dependencies all met for dep_context=requeueable deps ti=<TaskInstance: tesla_stock_sentiment__etl.load_stock_data_to_snowflake scheduled__2025-04-30T02:30:00+00:00 [queued]>
[2025-05-01T02:30:01.843+0000] {taskinstance.py:2865} INFO - Starting attempt 1 of 1
[2025-05-01T02:30:01.853+0000] {taskinstance.py:2888} INFO - Executing <Task(_PythonDecoratedOperator): load_stock_data_to_snowflake> on 2025-04-30 02:30:00+00:00
[2025-05-01T02:30:01.866+0000] {logging_mixin.py:190} WARNING - /home/***/.local/lib/python3.12/site-packages/***/task/task_runner/standard_task_runner.py:70 DeprecationWarning: This process (pid=5766) is multi-threaded, use of fork() may lead to deadlocks in the child.
[2025-05-01T02:30:01.868+0000] {standard_task_runner.py:72} INFO - Started process 5772 to run task
[2025-05-01T02:30:01.867+0000] {standard_task_runner.py:104} INFO - Running: ['***', 'tasks', 'run', 'tesla_stock_sentiment__etl', 'load_stock_data_to_snowflake', 'scheduled__2025-04-30T02:30:00+00:00', '--job-id', '44', '--raw', '--subdir', 'DAGS_FOLDER/tesla_stock_etl_api.py', '--cfg-path', '/tmp/tmp6dgpmczv']
[2025-05-01T02:30:01.871+0000] {standard_task_runner.py:105} INFO - Job 44: Subtask load_stock_data_to_snowflake
[2025-05-01T02:30:01.938+0000] {task_command.py:467} INFO - Running <TaskInstance: tesla_stock_sentiment__etl.load_stock_data_to_snowflake scheduled__2025-04-30T02:30:00+00:00 [running]> on host 04c21e6bd2dc
[2025-05-01T02:30:02.066+0000] {taskinstance.py:3131} INFO - Exporting env vars: AIRFLOW_CTX_DAG_OWNER='***' AIRFLOW_CTX_DAG_ID='tesla_stock_sentiment__etl' AIRFLOW_CTX_TASK_ID='load_stock_data_to_snowflake' AIRFLOW_CTX_EXECUTION_DATE='2025-04-30T02:30:00+00:00' AIRFLOW_CTX_TRY_NUMBER='1' AIRFLOW_CTX_DAG_RUN_ID='scheduled__2025-04-30T02:30:00+00:00'
[2025-05-01T02:30:02.069+0000] {taskinstance.py:731} INFO - ::endgroup::
[2025-05-01T02:30:02.093+0000] {base.py:84} INFO - Retrieving connection 'snowflake_conn'
[2025-05-01T02:30:02.096+0000] {connection.py:413} INFO - Snowflake Connector for Python Version: 3.12.1, Python Version: 3.12.5, Platform: Linux-6.12.5-linuxkit-aarch64-with-glibc2.36
[2025-05-01T02:30:02.097+0000] {connection.py:1196} INFO - Connecting to GLOBAL Snowflake domain
[2025-05-01T02:30:02.098+0000] {connection.py:1277} INFO - This connection is in OCSP Fail Open Mode. TLS Certificates would be checked for validity and revocation status. Any other Certificate Revocation related exceptions or OCSP Responder failures would be disregarded in favor of connectivity.
[2025-05-01T02:30:03.220+0000] {cursor.py:1156} INFO - Number of results in first chunk: 1
[2025-05-01T02:30:03.221+0000] {taskinstance.py:3310} ERROR - Task failed with exception
Traceback (most recent call last):
  File "/home/airflow/.local/lib/python3.12/site-packages/airflow/models/taskinstance.py", line 767, in _execute_task
    result = _execute_callable(context=context, **execute_callable_kwargs)
             ^^^^^^^^^^^^^^^^^^^^^^^^^^^^^^^^^^^^^^^^^^^^^^^^^^^^^^^^^^^^^
  File "/home/airflow/.local/lib/python3.12/site-packages/airflow/models/taskinstance.py", line 733, in _execute_callable
    return ExecutionCallableRunner(
           ^^^^^^^^^^^^^^^^^^^^^^^^
  File "/home/airflow/.local/lib/python3.12/site-packages/airflow/utils/operator_helpers.py", line 252, in run
    return self.func(*args, **kwargs)
           ^^^^^^^^^^^^^^^^^^^^^^^^^^
  File "/home/airflow/.local/lib/python3.12/site-packages/airflow/models/baseoperator.py", line 406, in wrapper
    return func(self, *args, **kwargs)
           ^^^^^^^^^^^^^^^^^^^^^^^^^^^
  File "/home/airflow/.local/lib/python3.12/site-packages/airflow/decorators/base.py", line 266, in execute
    return_value = super().execute(context)
                   ^^^^^^^^^^^^^^^^^^^^^^^^
  File "/home/airflow/.local/lib/python3.12/site-packages/airflow/models/baseoperator.py", line 406, in wrapper
    return func(self, *args, **kwargs)
           ^^^^^^^^^^^^^^^^^^^^^^^^^^^
  File "/home/airflow/.local/lib/python3.12/site-packages/airflow/operators/python.py", line 238, in execute
    return_value = self.execute_callable()
                   ^^^^^^^^^^^^^^^^^^^^^^^
  File "/home/airflow/.local/lib/python3.12/site-packages/airflow/operators/python.py", line 256, in execute_callable
    return runner.run(*self.op_args, **self.op_kwargs)
           ^^^^^^^^^^^^^^^^^^^^^^^^^^^^^^^^^^^^^^^^^^^
  File "/home/airflow/.local/lib/python3.12/site-packages/airflow/utils/operator_helpers.py", line 252, in run
    return self.func(*args, **kwargs)
           ^^^^^^^^^^^^^^^^^^^^^^^^^^
  File "/opt/airflow/dags/tesla_stock_etl_api.py", line 68, in load_stock_data_to_snowflake
    raise e
  File "/opt/airflow/dags/tesla_stock_etl_api.py", line 30, in load_stock_data_to_snowflake
    raise ValueError("Unexpected response from Alpha Vantage")
ValueError: Unexpected response from Alpha Vantage
[2025-05-01T02:30:03.238+0000] {taskinstance.py:1225} INFO - Marking task as FAILED. dag_id=tesla_stock_sentiment__etl, task_id=load_stock_data_to_snowflake, run_id=scheduled__2025-04-30T02:30:00+00:00, execution_date=20250430T023000, start_date=20250501T023001, end_date=20250501T023003
[2025-05-01T02:30:03.256+0000] {taskinstance.py:340} INFO - ::group::Post task execution logs
[2025-05-01T02:30:03.257+0000] {standard_task_runner.py:124} ERROR - Failed to execute job 44 for task load_stock_data_to_snowflake (Unexpected response from Alpha Vantage; 5772)
Traceback (most recent call last):
  File "/home/airflow/.local/lib/python3.12/site-packages/airflow/task/task_runner/standard_task_runner.py", line 117, in _start_by_fork
    ret = args.func(args, dag=self.dag)
          ^^^^^^^^^^^^^^^^^^^^^^^^^^^^^
  File "/home/airflow/.local/lib/python3.12/site-packages/airflow/cli/cli_config.py", line 49, in command
    return func(*args, **kwargs)
           ^^^^^^^^^^^^^^^^^^^^^
  File "/home/airflow/.local/lib/python3.12/site-packages/airflow/utils/cli.py", line 115, in wrapper
    return f(*args, **kwargs)
           ^^^^^^^^^^^^^^^^^^
  File "/home/airflow/.local/lib/python3.12/site-packages/airflow/cli/commands/task_command.py", line 483, in task_run
    task_return_code = _run_task_by_selected_method(args, _dag, ti)
                       ^^^^^^^^^^^^^^^^^^^^^^^^^^^^^^^^^^^^^^^^^^^^
  File "/home/airflow/.local/lib/python3.12/site-packages/airflow/cli/commands/task_command.py", line 256, in _run_task_by_selected_method
    return _run_raw_task(args, ti)
           ^^^^^^^^^^^^^^^^^^^^^^^
  File "/home/airflow/.local/lib/python3.12/site-packages/airflow/cli/commands/task_command.py", line 341, in _run_raw_task
    return ti._run_raw_task(
           ^^^^^^^^^^^^^^^^^
  File "/home/airflow/.local/lib/python3.12/site-packages/airflow/utils/session.py", line 97, in wrapper
    return func(*args, session=session, **kwargs)
           ^^^^^^^^^^^^^^^^^^^^^^^^^^^^^^^^^^^^^^
  File "/home/airflow/.local/lib/python3.12/site-packages/airflow/models/taskinstance.py", line 3004, in _run_raw_task
    return _run_raw_task(
           ^^^^^^^^^^^^^^
  File "/home/airflow/.local/lib/python3.12/site-packages/airflow/models/taskinstance.py", line 273, in _run_raw_task
    TaskInstance._execute_task_with_callbacks(
  File "/home/airflow/.local/lib/python3.12/site-packages/airflow/models/taskinstance.py", line 3158, in _execute_task_with_callbacks
    result = self._execute_task(context, task_orig)
             ^^^^^^^^^^^^^^^^^^^^^^^^^^^^^^^^^^^^^^
  File "/home/airflow/.local/lib/python3.12/site-packages/airflow/models/taskinstance.py", line 3182, in _execute_task
    return _execute_task(self, context, task_orig)
           ^^^^^^^^^^^^^^^^^^^^^^^^^^^^^^^^^^^^^^^
  File "/home/airflow/.local/lib/python3.12/site-packages/airflow/models/taskinstance.py", line 767, in _execute_task
    result = _execute_callable(context=context, **execute_callable_kwargs)
             ^^^^^^^^^^^^^^^^^^^^^^^^^^^^^^^^^^^^^^^^^^^^^^^^^^^^^^^^^^^^^
  File "/home/airflow/.local/lib/python3.12/site-packages/airflow/models/taskinstance.py", line 733, in _execute_callable
    return ExecutionCallableRunner(
           ^^^^^^^^^^^^^^^^^^^^^^^^
  File "/home/airflow/.local/lib/python3.12/site-packages/airflow/utils/operator_helpers.py", line 252, in run
    return self.func(*args, **kwargs)
           ^^^^^^^^^^^^^^^^^^^^^^^^^^
  File "/home/airflow/.local/lib/python3.12/site-packages/airflow/models/baseoperator.py", line 406, in wrapper
    return func(self, *args, **kwargs)
           ^^^^^^^^^^^^^^^^^^^^^^^^^^^
  File "/home/airflow/.local/lib/python3.12/site-packages/airflow/decorators/base.py", line 266, in execute
    return_value = super().execute(context)
                   ^^^^^^^^^^^^^^^^^^^^^^^^
  File "/home/airflow/.local/lib/python3.12/site-packages/airflow/models/baseoperator.py", line 406, in wrapper
    return func(self, *args, **kwargs)
           ^^^^^^^^^^^^^^^^^^^^^^^^^^^
  File "/home/airflow/.local/lib/python3.12/site-packages/airflow/operators/python.py", line 238, in execute
    return_value = self.execute_callable()
                   ^^^^^^^^^^^^^^^^^^^^^^^
  File "/home/airflow/.local/lib/python3.12/site-packages/airflow/operators/python.py", line 256, in execute_callable
    return runner.run(*self.op_args, **self.op_kwargs)
           ^^^^^^^^^^^^^^^^^^^^^^^^^^^^^^^^^^^^^^^^^^^
  File "/home/airflow/.local/lib/python3.12/site-packages/airflow/utils/operator_helpers.py", line 252, in run
    return self.func(*args, **kwargs)
           ^^^^^^^^^^^^^^^^^^^^^^^^^^
  File "/opt/airflow/dags/tesla_stock_etl_api.py", line 68, in load_stock_data_to_snowflake
    raise e
  File "/opt/airflow/dags/tesla_stock_etl_api.py", line 30, in load_stock_data_to_snowflake
    raise ValueError("Unexpected response from Alpha Vantage")
ValueError: Unexpected response from Alpha Vantage
[2025-05-01T02:30:03.304+0000] {local_task_job_runner.py:266} INFO - Task exited with return code 1
[2025-05-01T02:30:03.350+0000] {taskinstance.py:3900} INFO - 0 downstream tasks scheduled from follow-on schedule check
[2025-05-01T02:30:03.356+0000] {local_task_job_runner.py:245} INFO - ::endgroup::
