[0m14:22:18.490839 [debug] [MainThread]: Sending event: {'category': 'dbt', 'action': 'invocation', 'label': 'start', 'context': [<snowplow_tracker.self_describing_json.SelfDescribingJson object at 0x1053200b0>, <snowplow_tracker.self_describing_json.SelfDescribingJson object at 0x110789fa0>, <snowplow_tracker.self_describing_json.SelfDescribingJson object at 0x110789d30>]}


============================== 14:22:18.494729 | 0d03df43-01ad-48a9-920e-f8faf02ee7ff ==============================
[0m14:22:18.494729 [info ] [MainThread]: Running with dbt=1.9.4
[0m14:22:18.495227 [debug] [MainThread]: running dbt with arguments {'printer_width': '80', 'indirect_selection': 'eager', 'write_json': 'True', 'log_cache_events': 'False', 'partial_parse': 'True', 'cache_selected_only': 'False', 'warn_error': 'None', 'fail_fast': 'False', 'debug': 'False', 'log_path': 'logs', 'profiles_dir': '/Users/savithavijayarangan/.dbt', 'version_check': 'True', 'use_colors': 'True', 'use_experimental_parser': 'False', 'empty': 'None', 'quiet': 'False', 'no_print': 'None', 'log_format': 'default', 'invocation_command': 'dbt docs serve', 'warn_error_options': 'WarnErrorOptions(include=[], exclude=[])', 'introspect': 'True', 'target_path': 'None', 'static_parser': 'True', 'send_anonymous_usage_stats': 'True'}
[0m14:22:18.495704 [error] [MainThread]: Encountered an error:
Runtime Error
  No dbt_project.yml found at expected path /Users/savithavijayarangan/Downloads/DW_Project/dbt_project.yml
  Verify that each entry within packages.yml (and their transitive dependencies) contains a file named dbt_project.yml
  
[0m14:22:18.497718 [debug] [MainThread]: Resource report: {"command_name": "serve", "command_success": false, "command_wall_clock_time": 0.07771883, "process_in_blocks": "0", "process_kernel_time": 0.290608, "process_mem_max_rss": "105201664", "process_out_blocks": "0", "process_user_time": 1.242171}
[0m14:22:18.498186 [debug] [MainThread]: Command `dbt docs serve` failed at 14:22:18.498098 after 0.08 seconds
[0m14:22:18.498505 [debug] [MainThread]: Sending event: {'category': 'dbt', 'action': 'invocation', 'label': 'end', 'context': [<snowplow_tracker.self_describing_json.SelfDescribingJson object at 0x110789eb0>, <snowplow_tracker.self_describing_json.SelfDescribingJson object at 0x11078b950>, <snowplow_tracker.self_describing_json.SelfDescribingJson object at 0x11078b920>]}
[0m14:22:18.498800 [debug] [MainThread]: Flushing usage events
[0m14:22:19.012711 [debug] [MainThread]: An error was encountered while trying to flush usage events
