[2025-05-02T21:03:23.134+0000] {local_task_job_runner.py:123} INFO - ::group::Pre task execution logs
[2025-05-02T21:03:23.171+0000] {taskinstance.py:2612} INFO - Dependencies all met for dep_context=non-requeueable deps ti=<TaskInstance: sentiment_analysis_stock_ELT_dbt.dbt_run manual__2025-05-02T20:44:13.915927+00:00 [queued]>
[2025-05-02T21:03:23.181+0000] {taskinstance.py:2612} INFO - Dependencies all met for dep_context=requeueable deps ti=<TaskInstance: sentiment_analysis_stock_ELT_dbt.dbt_run manual__2025-05-02T20:44:13.915927+00:00 [queued]>
[2025-05-02T21:03:23.182+0000] {taskinstance.py:2865} INFO - Starting attempt 2 of 2
[2025-05-02T21:03:23.196+0000] {taskinstance.py:2888} INFO - Executing <Task(BashOperator): dbt_run> on 2025-05-02 20:44:13.915927+00:00
[2025-05-02T21:03:23.216+0000] {logging_mixin.py:190} WARNING - /home/***/.local/lib/python3.12/site-packages/***/task/task_runner/standard_task_runner.py:70 DeprecationWarning: This process (pid=342) is multi-threaded, use of fork() may lead to deadlocks in the child.
[2025-05-02T21:03:23.211+0000] {standard_task_runner.py:104} INFO - Running: ['***', 'tasks', 'run', 'sentiment_analysis_stock_ELT_dbt', 'dbt_run', 'manual__2025-05-02T20:44:13.915927+00:00', '--job-id', '71', '--raw', '--subdir', 'DAGS_FOLDER/sentiment_analysis_build_elt_with_dbt.py', '--cfg-path', '/tmp/tmpquji9a4q']
[2025-05-02T21:03:23.218+0000] {standard_task_runner.py:105} INFO - Job 71: Subtask dbt_run
[2025-05-02T21:03:23.218+0000] {standard_task_runner.py:72} INFO - Started process 343 to run task
[2025-05-02T21:03:23.299+0000] {task_command.py:467} INFO - Running <TaskInstance: sentiment_analysis_stock_ELT_dbt.dbt_run manual__2025-05-02T20:44:13.915927+00:00 [running]> on host 4bc692150671
[2025-05-02T21:03:23.382+0000] {taskinstance.py:3131} INFO - Exporting env vars: AIRFLOW_CTX_DAG_OWNER='***' AIRFLOW_CTX_DAG_ID='sentiment_analysis_stock_ELT_dbt' AIRFLOW_CTX_TASK_ID='dbt_run' AIRFLOW_CTX_EXECUTION_DATE='2025-05-02T20:44:13.915927+00:00' AIRFLOW_CTX_TRY_NUMBER='2' AIRFLOW_CTX_DAG_RUN_ID='manual__2025-05-02T20:44:13.915927+00:00'
[2025-05-02T21:03:23.384+0000] {taskinstance.py:731} INFO - ::endgroup::
[2025-05-02T21:03:23.409+0000] {subprocess.py:63} INFO - Tmp dir root location: /tmp
[2025-05-02T21:03:23.411+0000] {subprocess.py:75} INFO - Running command: ['/usr/bin/bash', '-c', '/home/***/.local/bin/dbt run --profiles-dir /opt/***/sentiment_analysis_dbt --project-dir /opt/***/sentiment_analysis_dbt']
[2025-05-02T21:03:23.421+0000] {subprocess.py:86} INFO - Output:
[2025-05-02T21:03:26.878+0000] {subprocess.py:93} INFO - [0m21:03:26  Running with dbt=1.7.19
[2025-05-02T21:03:26.884+0000] {subprocess.py:93} INFO - [0m21:03:26  Encountered an error:
[2025-05-02T21:03:26.885+0000] {subprocess.py:93} INFO - Runtime Error
[2025-05-02T21:03:26.885+0000] {subprocess.py:93} INFO -   No dbt_project.yml found at expected path /opt/***/sentiment_analysis_dbt/dbt_project.yml
[2025-05-02T21:03:26.886+0000] {subprocess.py:93} INFO -   Verify that each entry within packages.yml (and their transitive dependencies) contains a file named dbt_project.yml
[2025-05-02T21:03:26.886+0000] {subprocess.py:93} INFO - 
[2025-05-02T21:03:27.676+0000] {subprocess.py:97} INFO - Command exited with return code 2
[2025-05-02T21:03:27.714+0000] {taskinstance.py:3310} ERROR - Task failed with exception
Traceback (most recent call last):
  File "/home/airflow/.local/lib/python3.12/site-packages/airflow/models/taskinstance.py", line 767, in _execute_task
    result = _execute_callable(context=context, **execute_callable_kwargs)
             ^^^^^^^^^^^^^^^^^^^^^^^^^^^^^^^^^^^^^^^^^^^^^^^^^^^^^^^^^^^^^
  File "/home/airflow/.local/lib/python3.12/site-packages/airflow/models/taskinstance.py", line 733, in _execute_callable
    return ExecutionCallableRunner(
           ^^^^^^^^^^^^^^^^^^^^^^^^
  File "/home/airflow/.local/lib/python3.12/site-packages/airflow/utils/operator_helpers.py", line 252, in run
    return self.func(*args, **kwargs)
           ^^^^^^^^^^^^^^^^^^^^^^^^^^
  File "/home/airflow/.local/lib/python3.12/site-packages/airflow/models/baseoperator.py", line 406, in wrapper
    return func(self, *args, **kwargs)
           ^^^^^^^^^^^^^^^^^^^^^^^^^^^
  File "/home/airflow/.local/lib/python3.12/site-packages/airflow/operators/bash.py", line 249, in execute
    raise AirflowException(
airflow.exceptions.AirflowException: Bash command failed. The command returned a non-zero exit code 2.
[2025-05-02T21:03:27.724+0000] {taskinstance.py:1225} INFO - Marking task as FAILED. dag_id=sentiment_analysis_stock_ELT_dbt, task_id=dbt_run, run_id=manual__2025-05-02T20:44:13.915927+00:00, execution_date=20250502T204413, start_date=20250502T210323, end_date=20250502T210327
[2025-05-02T21:03:27.746+0000] {taskinstance.py:340} INFO - ::group::Post task execution logs
[2025-05-02T21:03:27.747+0000] {standard_task_runner.py:124} ERROR - Failed to execute job 71 for task dbt_run (Bash command failed. The command returned a non-zero exit code 2.; 343)
Traceback (most recent call last):
  File "/home/airflow/.local/lib/python3.12/site-packages/airflow/task/task_runner/standard_task_runner.py", line 117, in _start_by_fork
    ret = args.func(args, dag=self.dag)
          ^^^^^^^^^^^^^^^^^^^^^^^^^^^^^
  File "/home/airflow/.local/lib/python3.12/site-packages/airflow/cli/cli_config.py", line 49, in command
    return func(*args, **kwargs)
           ^^^^^^^^^^^^^^^^^^^^^
  File "/home/airflow/.local/lib/python3.12/site-packages/airflow/utils/cli.py", line 115, in wrapper
    return f(*args, **kwargs)
           ^^^^^^^^^^^^^^^^^^
  File "/home/airflow/.local/lib/python3.12/site-packages/airflow/cli/commands/task_command.py", line 483, in task_run
    task_return_code = _run_task_by_selected_method(args, _dag, ti)
                       ^^^^^^^^^^^^^^^^^^^^^^^^^^^^^^^^^^^^^^^^^^^^
  File "/home/airflow/.local/lib/python3.12/site-packages/airflow/cli/commands/task_command.py", line 256, in _run_task_by_selected_method
    return _run_raw_task(args, ti)
           ^^^^^^^^^^^^^^^^^^^^^^^
  File "/home/airflow/.local/lib/python3.12/site-packages/airflow/cli/commands/task_command.py", line 341, in _run_raw_task
    return ti._run_raw_task(
           ^^^^^^^^^^^^^^^^^
  File "/home/airflow/.local/lib/python3.12/site-packages/airflow/utils/session.py", line 97, in wrapper
    return func(*args, session=session, **kwargs)
           ^^^^^^^^^^^^^^^^^^^^^^^^^^^^^^^^^^^^^^
  File "/home/airflow/.local/lib/python3.12/site-packages/airflow/models/taskinstance.py", line 3004, in _run_raw_task
    return _run_raw_task(
           ^^^^^^^^^^^^^^
  File "/home/airflow/.local/lib/python3.12/site-packages/airflow/models/taskinstance.py", line 273, in _run_raw_task
    TaskInstance._execute_task_with_callbacks(
  File "/home/airflow/.local/lib/python3.12/site-packages/airflow/models/taskinstance.py", line 3158, in _execute_task_with_callbacks
    result = self._execute_task(context, task_orig)
             ^^^^^^^^^^^^^^^^^^^^^^^^^^^^^^^^^^^^^^
  File "/home/airflow/.local/lib/python3.12/site-packages/airflow/models/taskinstance.py", line 3182, in _execute_task
    return _execute_task(self, context, task_orig)
           ^^^^^^^^^^^^^^^^^^^^^^^^^^^^^^^^^^^^^^^
  File "/home/airflow/.local/lib/python3.12/site-packages/airflow/models/taskinstance.py", line 767, in _execute_task
    result = _execute_callable(context=context, **execute_callable_kwargs)
             ^^^^^^^^^^^^^^^^^^^^^^^^^^^^^^^^^^^^^^^^^^^^^^^^^^^^^^^^^^^^^
  File "/home/airflow/.local/lib/python3.12/site-packages/airflow/models/taskinstance.py", line 733, in _execute_callable
    return ExecutionCallableRunner(
           ^^^^^^^^^^^^^^^^^^^^^^^^
  File "/home/airflow/.local/lib/python3.12/site-packages/airflow/utils/operator_helpers.py", line 252, in run
    return self.func(*args, **kwargs)
           ^^^^^^^^^^^^^^^^^^^^^^^^^^
  File "/home/airflow/.local/lib/python3.12/site-packages/airflow/models/baseoperator.py", line 406, in wrapper
    return func(self, *args, **kwargs)
           ^^^^^^^^^^^^^^^^^^^^^^^^^^^
  File "/home/airflow/.local/lib/python3.12/site-packages/airflow/operators/bash.py", line 249, in execute
    raise AirflowException(
airflow.exceptions.AirflowException: Bash command failed. The command returned a non-zero exit code 2.
[2025-05-02T21:03:27.808+0000] {local_task_job_runner.py:266} INFO - Task exited with return code 1
[2025-05-02T21:03:27.849+0000] {taskinstance.py:3900} INFO - 0 downstream tasks scheduled from follow-on schedule check
[2025-05-02T21:03:27.859+0000] {local_task_job_runner.py:245} INFO - ::endgroup::
