[2025-05-02T21:11:14.902+0000] {local_task_job_runner.py:123} INFO - ::group::Pre task execution logs
[2025-05-02T21:11:14.960+0000] {taskinstance.py:2612} INFO - Dependencies all met for dep_context=non-requeueable deps ti=<TaskInstance: sentiment_analysis_stock_ELT_dbt.dbt_linage manual__2025-05-02T20:44:13.915927+00:00 [queued]>
[2025-05-02T21:11:14.974+0000] {taskinstance.py:2612} INFO - Dependencies all met for dep_context=requeueable deps ti=<TaskInstance: sentiment_analysis_stock_ELT_dbt.dbt_linage manual__2025-05-02T20:44:13.915927+00:00 [queued]>
[2025-05-02T21:11:14.975+0000] {taskinstance.py:2865} INFO - Starting attempt 1 of 1
[2025-05-02T21:11:14.990+0000] {taskinstance.py:2888} INFO - Executing <Task(BashOperator): dbt_linage> on 2025-05-02 20:44:13.915927+00:00
[2025-05-02T21:11:14.999+0000] {standard_task_runner.py:104} INFO - Running: ['***', 'tasks', 'run', 'sentiment_analysis_stock_ELT_dbt', 'dbt_linage', 'manual__2025-05-02T20:44:13.915927+00:00', '--job-id', '78', '--raw', '--subdir', 'DAGS_FOLDER/sentiment_analysis_build_elt_with_dbt.py', '--cfg-path', '/tmp/tmp4yllmbr4']
[2025-05-02T21:11:15.004+0000] {standard_task_runner.py:105} INFO - Job 78: Subtask dbt_linage
[2025-05-02T21:11:15.004+0000] {logging_mixin.py:190} WARNING - /home/***/.local/lib/python3.12/site-packages/***/task/task_runner/standard_task_runner.py:70 DeprecationWarning: This process (pid=451) is multi-threaded, use of fork() may lead to deadlocks in the child.
[2025-05-02T21:11:15.007+0000] {standard_task_runner.py:72} INFO - Started process 452 to run task
[2025-05-02T21:11:15.059+0000] {task_command.py:467} INFO - Running <TaskInstance: sentiment_analysis_stock_ELT_dbt.dbt_linage manual__2025-05-02T20:44:13.915927+00:00 [running]> on host 4ad8ada818c7
[2025-05-02T21:11:15.123+0000] {taskinstance.py:3131} INFO - Exporting env vars: AIRFLOW_CTX_DAG_OWNER='***' AIRFLOW_CTX_DAG_ID='sentiment_analysis_stock_ELT_dbt' AIRFLOW_CTX_TASK_ID='dbt_linage' AIRFLOW_CTX_EXECUTION_DATE='2025-05-02T20:44:13.915927+00:00' AIRFLOW_CTX_TRY_NUMBER='1' AIRFLOW_CTX_DAG_RUN_ID='manual__2025-05-02T20:44:13.915927+00:00'
[2025-05-02T21:11:15.123+0000] {taskinstance.py:731} INFO - ::endgroup::
[2025-05-02T21:11:15.138+0000] {subprocess.py:63} INFO - Tmp dir root location: /tmp
[2025-05-02T21:11:15.142+0000] {subprocess.py:75} INFO - Running command: ['/usr/bin/bash', '-c', '/home/***/.local/bin/dbt docs serve  --profiles-dir /opt/***/sentiment_analysis_dbt --project-dir /opt/***/sentiment_analysis_dbt']
[2025-05-02T21:11:15.148+0000] {subprocess.py:86} INFO - Output:
[2025-05-02T21:11:17.868+0000] {subprocess.py:93} INFO - [0m21:11:17  Running with dbt=1.7.19
[2025-05-02T21:11:18.891+0000] {subprocess.py:93} INFO - [0m21:11:18  Encountered an error:
[2025-05-02T21:11:18.895+0000] {subprocess.py:93} INFO - [Errno 98] Address already in use
[2025-05-02T21:11:18.896+0000] {subprocess.py:93} INFO - [0m21:11:18  Traceback (most recent call last):
[2025-05-02T21:11:18.897+0000] {subprocess.py:93} INFO -   File "/home/***/.local/lib/python3.12/site-packages/dbt/cli/requires.py", line 91, in wrapper
[2025-05-02T21:11:18.899+0000] {subprocess.py:93} INFO -     result, success = func(*args, **kwargs)
[2025-05-02T21:11:18.899+0000] {subprocess.py:93} INFO -                       ^^^^^^^^^^^^^^^^^^^^^
[2025-05-02T21:11:18.900+0000] {subprocess.py:93} INFO -   File "/home/***/.local/lib/python3.12/site-packages/dbt/cli/requires.py", line 76, in wrapper
[2025-05-02T21:11:18.900+0000] {subprocess.py:93} INFO -     return func(*args, **kwargs)
[2025-05-02T21:11:18.900+0000] {subprocess.py:93} INFO -            ^^^^^^^^^^^^^^^^^^^^^
[2025-05-02T21:11:18.901+0000] {subprocess.py:93} INFO -   File "/home/***/.local/lib/python3.12/site-packages/dbt/cli/requires.py", line 169, in wrapper
[2025-05-02T21:11:18.901+0000] {subprocess.py:93} INFO -     return func(*args, **kwargs)
[2025-05-02T21:11:18.901+0000] {subprocess.py:93} INFO -            ^^^^^^^^^^^^^^^^^^^^^
[2025-05-02T21:11:18.901+0000] {subprocess.py:93} INFO -   File "/home/***/.local/lib/python3.12/site-packages/dbt/cli/requires.py", line 198, in wrapper
[2025-05-02T21:11:18.902+0000] {subprocess.py:93} INFO -     return func(*args, **kwargs)
[2025-05-02T21:11:18.902+0000] {subprocess.py:93} INFO -            ^^^^^^^^^^^^^^^^^^^^^
[2025-05-02T21:11:18.902+0000] {subprocess.py:93} INFO -   File "/home/***/.local/lib/python3.12/site-packages/dbt/cli/requires.py", line 245, in wrapper
[2025-05-02T21:11:18.902+0000] {subprocess.py:93} INFO -     return func(*args, **kwargs)
[2025-05-02T21:11:18.902+0000] {subprocess.py:93} INFO -            ^^^^^^^^^^^^^^^^^^^^^
[2025-05-02T21:11:18.902+0000] {subprocess.py:93} INFO -   File "/home/***/.local/lib/python3.12/site-packages/dbt/cli/main.py", line 325, in docs_serve
[2025-05-02T21:11:18.903+0000] {subprocess.py:93} INFO -     results = task.run()
[2025-05-02T21:11:18.903+0000] {subprocess.py:93} INFO -               ^^^^^^^^^^
[2025-05-02T21:11:18.903+0000] {subprocess.py:93} INFO -   File "/home/***/.local/lib/python3.12/site-packages/dbt/task/serve.py", line 24, in run
[2025-05-02T21:11:18.903+0000] {subprocess.py:93} INFO -     with socketserver.TCPServer((host, port), SimpleHTTPRequestHandler) as httpd:
[2025-05-02T21:11:18.904+0000] {subprocess.py:93} INFO -          ^^^^^^^^^^^^^^^^^^^^^^^^^^^^^^^^^^^^^^^^^^^^^^^^^^^^^^^^^^^^^^
[2025-05-02T21:11:18.904+0000] {subprocess.py:93} INFO -   File "/usr/local/lib/python3.12/socketserver.py", line 457, in __init__
[2025-05-02T21:11:18.904+0000] {subprocess.py:93} INFO -     self.server_bind()
[2025-05-02T21:11:18.904+0000] {subprocess.py:93} INFO -   File "/usr/local/lib/python3.12/socketserver.py", line 473, in server_bind
[2025-05-02T21:11:18.905+0000] {subprocess.py:93} INFO -     self.socket.bind(self.server_address)
[2025-05-02T21:11:18.905+0000] {subprocess.py:93} INFO - OSError: [Errno 98] Address already in use
[2025-05-02T21:11:18.906+0000] {subprocess.py:93} INFO - 
[2025-05-02T21:11:19.618+0000] {subprocess.py:97} INFO - Command exited with return code 2
[2025-05-02T21:11:19.692+0000] {taskinstance.py:3310} ERROR - Task failed with exception
Traceback (most recent call last):
  File "/home/airflow/.local/lib/python3.12/site-packages/airflow/models/taskinstance.py", line 767, in _execute_task
    result = _execute_callable(context=context, **execute_callable_kwargs)
             ^^^^^^^^^^^^^^^^^^^^^^^^^^^^^^^^^^^^^^^^^^^^^^^^^^^^^^^^^^^^^
  File "/home/airflow/.local/lib/python3.12/site-packages/airflow/models/taskinstance.py", line 733, in _execute_callable
    return ExecutionCallableRunner(
           ^^^^^^^^^^^^^^^^^^^^^^^^
  File "/home/airflow/.local/lib/python3.12/site-packages/airflow/utils/operator_helpers.py", line 252, in run
    return self.func(*args, **kwargs)
           ^^^^^^^^^^^^^^^^^^^^^^^^^^
  File "/home/airflow/.local/lib/python3.12/site-packages/airflow/models/baseoperator.py", line 406, in wrapper
    return func(self, *args, **kwargs)
           ^^^^^^^^^^^^^^^^^^^^^^^^^^^
  File "/home/airflow/.local/lib/python3.12/site-packages/airflow/operators/bash.py", line 249, in execute
    raise AirflowException(
airflow.exceptions.AirflowException: Bash command failed. The command returned a non-zero exit code 2.
[2025-05-02T21:11:19.705+0000] {taskinstance.py:1225} INFO - Marking task as FAILED. dag_id=sentiment_analysis_stock_ELT_dbt, task_id=dbt_linage, run_id=manual__2025-05-02T20:44:13.915927+00:00, execution_date=20250502T204413, start_date=20250502T211114, end_date=20250502T211119
[2025-05-02T21:11:19.735+0000] {taskinstance.py:340} INFO - ::group::Post task execution logs
[2025-05-02T21:11:19.737+0000] {standard_task_runner.py:124} ERROR - Failed to execute job 78 for task dbt_linage (Bash command failed. The command returned a non-zero exit code 2.; 452)
Traceback (most recent call last):
  File "/home/airflow/.local/lib/python3.12/site-packages/airflow/task/task_runner/standard_task_runner.py", line 117, in _start_by_fork
    ret = args.func(args, dag=self.dag)
          ^^^^^^^^^^^^^^^^^^^^^^^^^^^^^
  File "/home/airflow/.local/lib/python3.12/site-packages/airflow/cli/cli_config.py", line 49, in command
    return func(*args, **kwargs)
           ^^^^^^^^^^^^^^^^^^^^^
  File "/home/airflow/.local/lib/python3.12/site-packages/airflow/utils/cli.py", line 115, in wrapper
    return f(*args, **kwargs)
           ^^^^^^^^^^^^^^^^^^
  File "/home/airflow/.local/lib/python3.12/site-packages/airflow/cli/commands/task_command.py", line 483, in task_run
    task_return_code = _run_task_by_selected_method(args, _dag, ti)
                       ^^^^^^^^^^^^^^^^^^^^^^^^^^^^^^^^^^^^^^^^^^^^
  File "/home/airflow/.local/lib/python3.12/site-packages/airflow/cli/commands/task_command.py", line 256, in _run_task_by_selected_method
    return _run_raw_task(args, ti)
           ^^^^^^^^^^^^^^^^^^^^^^^
  File "/home/airflow/.local/lib/python3.12/site-packages/airflow/cli/commands/task_command.py", line 341, in _run_raw_task
    return ti._run_raw_task(
           ^^^^^^^^^^^^^^^^^
  File "/home/airflow/.local/lib/python3.12/site-packages/airflow/utils/session.py", line 97, in wrapper
    return func(*args, session=session, **kwargs)
           ^^^^^^^^^^^^^^^^^^^^^^^^^^^^^^^^^^^^^^
  File "/home/airflow/.local/lib/python3.12/site-packages/airflow/models/taskinstance.py", line 3004, in _run_raw_task
    return _run_raw_task(
           ^^^^^^^^^^^^^^
  File "/home/airflow/.local/lib/python3.12/site-packages/airflow/models/taskinstance.py", line 273, in _run_raw_task
    TaskInstance._execute_task_with_callbacks(
  File "/home/airflow/.local/lib/python3.12/site-packages/airflow/models/taskinstance.py", line 3158, in _execute_task_with_callbacks
    result = self._execute_task(context, task_orig)
             ^^^^^^^^^^^^^^^^^^^^^^^^^^^^^^^^^^^^^^
  File "/home/airflow/.local/lib/python3.12/site-packages/airflow/models/taskinstance.py", line 3182, in _execute_task
    return _execute_task(self, context, task_orig)
           ^^^^^^^^^^^^^^^^^^^^^^^^^^^^^^^^^^^^^^^
  File "/home/airflow/.local/lib/python3.12/site-packages/airflow/models/taskinstance.py", line 767, in _execute_task
    result = _execute_callable(context=context, **execute_callable_kwargs)
             ^^^^^^^^^^^^^^^^^^^^^^^^^^^^^^^^^^^^^^^^^^^^^^^^^^^^^^^^^^^^^
  File "/home/airflow/.local/lib/python3.12/site-packages/airflow/models/taskinstance.py", line 733, in _execute_callable
    return ExecutionCallableRunner(
           ^^^^^^^^^^^^^^^^^^^^^^^^
  File "/home/airflow/.local/lib/python3.12/site-packages/airflow/utils/operator_helpers.py", line 252, in run
    return self.func(*args, **kwargs)
           ^^^^^^^^^^^^^^^^^^^^^^^^^^
  File "/home/airflow/.local/lib/python3.12/site-packages/airflow/models/baseoperator.py", line 406, in wrapper
    return func(self, *args, **kwargs)
           ^^^^^^^^^^^^^^^^^^^^^^^^^^^
  File "/home/airflow/.local/lib/python3.12/site-packages/airflow/operators/bash.py", line 249, in execute
    raise AirflowException(
airflow.exceptions.AirflowException: Bash command failed. The command returned a non-zero exit code 2.
[2025-05-02T21:11:19.801+0000] {local_task_job_runner.py:266} INFO - Task exited with return code 1
[2025-05-02T21:11:19.839+0000] {taskinstance.py:3900} INFO - 0 downstream tasks scheduled from follow-on schedule check
[2025-05-02T21:11:19.841+0000] {local_task_job_runner.py:245} INFO - ::endgroup::
